2025-02-04 17:07:24,607 - exception_logger - ERROR - An exception occurred
Traceback (most recent call last):
  File "C:\Users\dell\AppData\Local\Temp\ipykernel_11356\2556711270.py", line 11, in <module>
    1 / 0
    ~~^~~
ZeroDivisionError: division by zero
